Workbook

Sheet Start
B2: Footprint Intelligence | ROI Calculator
B3: What does sustainability management cost you today – and how much time and money could Footprint Intelligence save?
B5: How to use this calculator
B6: 1 | C6: Inputs | D6: Enter your company profile, people involved, salaries and current costs in the yellow cells.
B7: 2 | C7: Activities | D7: Review the hours per activity. Defaults are benchmarks – replace them with your own estimates where you know them.
B8: 3 | C8: Results | D8: Management summary: time saved, net benefit, 3-year ROI, payback, scenarios and charts.
C9: Tip | D9: Start with the defaults to get a quick estimate in 2 minutes, then refine the activities for a detailed assessment.
B11: Colour legend
C12: Input | D12: Enter or change these values
C13: Calculated | D13: Formulas – no need to change
C14: Benchmark | D14: Typical default values, driven by your inputs
B16: How the calculation works
C17: Cost per hour | D17: Avg. gross salary × (1 + employer on-costs) ÷ productive hours per year
C18: Time value saved | D18: (Hours today − hours with FI) × cost per hour, per activity
C19: Current annual cost | D19: Internal staff time + software + factor databases + external services
C20: Annual cost with FI | D20: Remaining internal time + FI subscription + remaining external costs
C21: Year-1 net benefit | D21: Time value × ramp-up share + cash savings − FI subscription − one-time transition costs
C22: 3-year ROI | D22: (3-year cost today − 3-year cost with FI) ÷ 3-year cost with FI
C23: Payback | D23: First month in which the cumulative net benefit turns positive
B25: Important note
C26: This calculator provides an indicative estimate based on your inputs and typical benchmarks. It is not a binding offer or a guarantee of savings. Footprint Intelligence pricing is based on your individual offer.
C28: footprint-intelligence.com

Sheet Inputs
B2: Footprint Intelligence | ROI Calculator
B3: Step 1 of 3 – Inputs. Enter your figures in the yellow cells; everything else is calculated. All defaults are typical values and can be changed.
B5: 1 Company profile & approach
B6: Company name | C6: Your company | D6: Shown on the Results page
B7: Current approach | C7: Manual / Excel | D7: How sustainability data is managed today
B8: Share of FI savings already covered by your current tool | C8: 0 | D8: 0% for Manual / Excel. If you already use software, estimate how much of the automation it already provides (e.g. 30–50%). Avoids crediting FI for capabilities you already have.
B9: Data collection rounds per year | C9: 1 | D9: 1 = annual, 2 = semi-annual, 4 = quarterly, 12 = monthly
B10: Scenario shown in headline results | C10: Expected | D10: Conservative / Expected / Optimistic – all three are compared on the Results page
B12: 2 Complexity
B13: Legal entities in scope | C13: 5 | D13: Companies / subsidiaries included in reporting
B14: Sites / locations | C14: 30 | D14: Offices, plants, warehouses that deliver data
B15: Reporting frameworks & standards | C15: 3 | D15: e.g. GHG Protocol, CSRD / ESRS, VSME, CDP, EcoVadis, SBTi
B16: Customer & supplier questionnaires answered per year | C16: 10 | D16: Sustainability questionnaires, ratings and tender requests
B17: Key suppliers asked for data per year | C17: 20 | D17: Suppliers asked for emissions or ESG data
B18: Products requiring a product carbon footprint (PCF) per year | C18: 5 | D18: Only used if the PCF module is in scope
B20: 3 Modules in scope
B21: Carbon accounting (corporate carbon footprint) | C21: Yes
B22: ESG / CSRD reporting | C22: Yes
B23: Product carbon footprints (PCF) | C23: No
B24: Supply chain & questionnaires | C24: Yes
B25: Decarbonization planning | C25: Yes
B26: Core data management and reporting activities are always included.
B28: 4 People involved & internal cost per hour
B29: Role | C29: People involved | D29: Avg. annual gross salary (€) | E29: Employer on-costs (%) | F29: Productive hours per person / year | G29: Fully loaded cost per hour (€) | H29: Typical tasks
B30: Sustainability team (full-time) | C30: 2 | D30: 70000 | E30: 0.25 | F30: 1600 | G30: =IFERROR(D30*(1+E30)/F30,0) -> 54.6875 | H30: Coordination, data preparation, calculation, reporting
B31: Data providers (sites, HR, facilities, fleet) | C31: 25 | D31: 55000 | E31: 0.25 | F31: 1600 | G31: =IFERROR(D31*(1+E31)/F31,0) -> 42.96875 | H31: Providing energy, travel, waste, HR and other source data
B32: Finance & controlling | C32: 2 | D32: 75000 | E32: 0.25 | F32: 1600 | G32: =IFERROR(D32*(1+E32)/F32,0) -> 58.59375 | H32: Consolidation, reconciliation with financial data
B33: Procurement | C33: 1 | D33: 65000 | E33: 0.25 | F33: 1600 | G33: =IFERROR(D33*(1+E33)/F33,0) -> 50.78125 | H33: Supplier data requests and supplier engagement
B34: Management & reviewers | C34: 2 | D34: 120000 | E34: 0.25 | F34: 1600 | G34: =IFERROR(D34*(1+E34)/F34,0) -> 93.75 | H34: Reviews, approvals and sign-off
B36: 5 Annual external costs
B37: Cost item | C37: Today (€ / year) | D37: Still needed with FI (%) | E37: With FI (€ / year) | F37: Note
B38: Current sustainability / ESG software licence(s) | C38: 0 | D38: 0 | E38: =C38*D38 -> 0 | F38: Licences FI would replace. 0 for Manual / Excel – compare with another tool in section 8.
B39: Emission factor databases & data subscriptions | C39: 5000 | D39: 0 | E39: =C39*D39 -> 0 | F39: Maintained factor databases are included in Footprint Intelligence
B40: External consultants (data, calculation, reporting) | C40: 15000 | D40: 0.5 | E40: =C40*D40 -> 7500 | F40: Share of consulting still needed for strategy or special topics
B41: Other external services (report design, translation, etc.) | C41: 0 | D41: 1 | E41: =C41*D41 -> 0
B42: Footprint Intelligence annual subscription (as per your offer) | C42: – | E42: 39000 | F42: Price according to your individual offer
B43: Total annual external costs | C43: =SUM(C38:C42) -> 20000 | E43: =SUM(E38:E42) -> 46500
B45: 6 One-time transition costs (year 1)
B46: Item | C46: Input | D46: Cost (€) | E46: Note
B47: FI implementation / onboarding fee (€, as per your offer) | C47: 0 | D47: =C47 -> 0 | E47: One-time fee, if part of your offer
...

Sheet Activities
B2: Footprint Intelligence | ROI Calculator
B3: Step 2 of 3 – Activities. Hours today are benchmarks driven by your inputs. Overwrite them in the yellow 'Your estimate' column, and adjust who does the work and the expected reduction if needed.
N4: Scenario factor vs. expected → | O4: 0.7 | P4: 1 | Q4: 1.25
B5: Activity | H5: Benchmark | M5: Today | O5: Expected time reduction with FI | S5: With Footprint Intelligence
B6: # | C6: Activity | D6: How Footprint Intelligence helps | E6: Module | F6: In scope? | G6: Done by | H6: Fixed hours / year | I6: Hours per unit | J6: Driver | K6: Units | L6: Benchmark hours / year | M6: Your estimate (hours / year, optional) | N6: Hours today / year | O6: Conservative | P6: Expected (enter) | Q6: Optimistic | R6: Applied reduction* | S6: Hours with FI / year | T6: Hours saved / year | U6: Cost per hour (€) | V6: Value of time released (€ / year)
B7: 1 | C7: Data requesting & import | D7: Excel/CSV imports, document and electricity bill extraction, system integrations | E7: Core | F7: =_xlfn.XLOOKUP(E7,Calculations!$B$13:$B$18,Calculations!$C$13:$C$18,"No") -> Yes | G7: Sustainability team (full-time) | H7: 40 | I7: 8 | J7: Locations × rounds | K7: =_xlfn.XLOOKUP(J7,Calculations!$E$13:$E$22,Calculations!$F$13:$F$22,0) -> 30 | L7: =IF(F7="Yes",H7+I7*K7,0) -> 280 | N7: =IF(F7="Yes",IF(M7="",L7,M7),0) -> 280 | O7: =MIN(P7*$O$4,0.95) -> 0.385 | P7: 0.55 | Q7: =MIN(P7*$Q$4,0.95) -> 0.6875 | R7: {=INDEX(O7:Q7,Calculations!$I$13)*(1-Inputs!$C$8)} -> 0.55 | S7: =N7*(1-R7) -> 126 | T7: =N7-S7 -> 154 | U7: =_xlfn.XLOOKUP(G7,Inputs!$B$30:$B$34,Inputs!$G$30:$G$34,0) -> 54.6875 | V7: =T7*U7 -> 8421.875
B8: 2 | C8: Providing data (contributors' own time) | D8: Guided input forms and file uploads with AI extraction instead of re-typing | E8: Core | F8: =_xlfn.XLOOKUP(E8,Calculations!$B$13:$B$18,Calculations!$C$13:$C$18,"No") -> Yes | G8: Data providers (sites, HR, facilities, fleet) | H8: 0 | I8: 12 | J8: Data providers × rounds | K8: =_xlfn.XLOOKUP(J8,Calculations!$E$13:$E$22,Calculations!$F$13:$F$22,0) -> 25 | L8: =IF(F8="Yes",H8+I8*K8,0) -> 300 | N8: =IF(F8="Yes",IF(M8="",L8,M8),0) -> 300 | O8: =MIN(P8*$O$4,0.95) -> 0.315 | P8: 0.45 | Q8: =MIN(P8*$Q$4,0.95) -> 0.5625 | R8: {=INDEX(O8:Q8,Calculations!$I$13)*(1-Inputs!$C$8)} -> 0.45 | S8: =N8*(1-R8) -> 165 | T8: =N8-S8 -> 135 | U8: =_xlfn.XLOOKUP(G8,Inputs!$B$30:$B$34,Inputs!$G$30:$G$34,0) -> 42.96875 | V8: =T8*U8 -> 5800.7812
B9: 3 | C9: Data preparation & mapping | D9: AI-assisted classification, mapping and structuring; mappings are reused next period | E9: Core | F9: =_xlfn.XLOOKUP(E9,Calculations!$B$13:$B$18,Calculations!$C$13:$C$18,"No") -> Yes | G9: Sustainability team (full-time) | H9: 40 | I9: 6 | J9: Locations × rounds | K9: =_xlfn.XLOOKUP(J9,Calculations!$E$13:$E$22,Calculations!$F$13:$F$22,0) -> 30 | L9: =IF(F9="Yes",H9+I9*K9,0) -> 220 | N9: =IF(F9="Yes",IF(M9="",L9,M9),0) -> 220 | O9: =MIN(P9*$O$4,0.95) -> 0.455 | P9: 0.65 | Q9: =MIN(P9*$Q$4,0.95) -> 0.8125 | R9: {=INDEX(O9:Q9,Calculations!$I$13)*(1-Inputs!$C$8)} -> 0.65 | S9: =N9*(1-R9) -> 77 | T9: =N9-S9 -> 143 | U9: =_xlfn.XLOOKUP(G9,Inputs!$B$30:$B$34,Inputs!$G$30:$G$34,0) -> 54.6875 | V9: =T9*U9 -> 7820.3125
B10: 4 | C10: Emission factor research & maintenance | D10: Centrally maintained factor databases with reporting-year consistency | E10: Carbon accounting | F10: =_xlfn.XLOOKUP(E10,Calculations!$B$13:$B$18,Calculations!$C$13:$C$18,"No") -> Yes | G10: Sustainability team (full-time) | H10: 40 | I10: 4 | J10: Entities | K10: =_xlfn.XLOOKUP(J10,Calculations!$E$13:$E$22,Calculations!$F$13:$F$22,0) -> 5 | L10: =IF(F10="Yes",H10+I10*K10,0) -> 60 | N10: =IF(F10="Yes",IF(M10="",L10,M10),0) -> 60 | O10: =MIN(P10*$O$4,0.95) -> 0.525 | P10: 0.75 | Q10: =MIN(P10*$Q$4,0.95) -> 0.9375 | R10: {=INDEX(O10:Q10,Calculations!$I$13)*(1-Inputs!$C$8)} -> 0.75 | S10: =N10*(1-R10) -> 15 | T10: =N10-S10 -> 45 | U10: =_xlfn.XLOOKUP(G10,Inputs!$B$30:$B$34,Inputs!$G$30:$G$34,0) -> 54.6875 | V10: =T10*U10 -> 2460.9375
B11: 5 | C11: Calculations & consolidation | D11: Automated calculation and aggregation across entities and locations | E11: Carbon accounting | F11: =_xlfn.XLOOKUP(E11,Calculations!$B$13:$B$18,Calculations!$C$13:$C$18,"No") -> Yes | G11: Finance & controlling | H11: 40 | I11: 12 | J11: Entities × rounds | K11: =_xlfn.XLOOKUP(J11,Calculations!$E$13:$E$22,Calculations!$F$13:$F$22,0) -> 5 | L11: =IF(F11="Yes",H11+I11*K11,0) -> 100 | N11: =IF(F11="Yes",IF(M11="",L11,M11),0) -> 100 | O11: =MIN(P11*$O$4,0.95) -> 0.525 | P11: 0.75 | Q11: =MIN(P11*$Q$4,0.95) -> 0.9375 | R11: {=INDEX(O11:Q11,Calculations!$I$13)*(1-Inputs!$C$8)} -> 0.75 | S11: =N11*(1-R11) -> 25 | T11: =N11-S11 -> 75 | U11: =_xlfn.XLOOKUP(G11,Inputs!$B$30:$B$34,Inputs!$G$30:$G$34,0) -> 58.59375 | V11: =T11*U11 -> 4394.5312
B12: 6 | C12: Data validation & correction cycles | D12: AI-assisted plausibility checks, review workflows and structured approvals | E12: Core | F12: =_xlfn.XLOOKUP(E12,Calculations!$B$13:$B$18,Calculations!$C$13:$C$18,"No") -> Yes | G12: Sustainability team (full-time) | H12: 30 | I12: 5 | J12: Locations × rounds | K12: =_xlfn.XLOOKUP(J12,Calculations!$E$13:$E$22,Calculations!$F$13:$F$22,0) -> 30 | L12: =IF(F12="Yes",H12+I12*K12,0) -> 180 | N12: =IF(F12="Yes",IF(M12="",L12,M12),0) -> 180 | O12: =MIN(P12*$O$4,0.95) -> 0.315 | P12: 0.45 | Q12: =MIN(P12*$Q$4,0.95) -> 0.5625 | R12: {=INDEX(O12:Q12,Calculations!$I$13)*(1-Inputs!$C$8)} -> 0.45 | S12: =N12*(1-R12) -> 99 | T12: =N12-S12 -> 81 | U12: =_xlfn.XLOOKUP(G12,Inputs!$B$30:$B$34,Inputs!$G$30:$G$34,0) -> 54.6875 | V12: =T12*U12 -> 4429.6875
B13: 7 | C13: Task coordination & chasing contributors | D13: Assignments, deadlines, automatic reminders and status tracking | E13: Core | F13: =_xlfn.XLOOKUP(E13,Calculations!$B$13:$B$18,Calculations!$C$13:$C$18,"No") -> Yes | G13: Sustainability team (full-time) | H13: 20 | I13: 3 | J13: Data providers × rounds | K13: =_xlfn.XLOOKUP(J13,Calculations!$E$13:$E$22,Calculations!$F$13:$F$22,0) -> 25 | L13: =IF(F13="Yes",H13+I13*K13,0) -> 95 | N13: =IF(F13="Yes",IF(M13="",L13,M13),0) -> 95 | O13: =MIN(P13*$O$4,0.95) -> 0.42 | P13: 0.6 | Q13: =MIN(P13*$Q$4,0.95) -> 0.75 | R13: {=INDEX(O13:Q13,Calculations!$I$13)*(1-Inputs!$C$8)} -> 0.6 | S13: =N13*(1-R13) -> 38 | T13: =N13-S13 -> 57 | U13: =_xlfn.XLOOKUP(G13,Inputs!$B$30:$B$34,Inputs!$G$30:$G$34,0) -> 54.6875 | V13: =T13*U13 -> 3117.1875
B14: 8 | C14: Regulatory requirements & gap analysis | D14: Framework structures, guidance and mapping of existing data to disclosures | E14: ESG reporting | F14: =_xlfn.XLOOKUP(E14,Calculations!$B$13:$B$18,Calculations!$C$13:$C$18,"No") -> Yes | G14: Sustainability team (full-time) | H14: 20 | I14: 30 | J14: Frameworks | K14: =_xlfn.XLOOKUP(J14,Calculations!$E$13:$E$22,Calculations!$F$13:$F$22,0) -> 3 | L14: =IF(F14="Yes",H14+I14*K14,0) -> 110 | N14: =IF(F14="Yes",IF(M14="",L14,M14),0) -> 110 | O14: =MIN(P14*$O$4,0.95) -> 0.245 | P14: 0.35 | Q14: =MIN(P14*$Q$4,0.95) -> 0.4375 | R14: {=INDEX(O14:Q14,Calculations!$I$13)*(1-Inputs!$C$8)} -> 0.35 | S14: =N14*(1-R14) -> 71.5 | T14: =N14-S14 -> 38.5 | U14: =_xlfn.XLOOKUP(G14,Inputs!$B$30:$B$34,Inputs!$G$30:$G$34,0) -> 54.6875 | V14: =T14*U14 -> 2105.4688
B15: 9 | C15: Narrative drafting | D15: AI-assisted draft answers based on existing inputs – human review retained | E15: ESG reporting | F15: =_xlfn.XLOOKUP(E15,Calculations!$B$13:$B$18,Calculations!$C$13:$C$18,"No") -> Yes | G15: Sustainability team (full-time) | H15: 0 | I15: 40 | J15: Frameworks | K15: =_xlfn.XLOOKUP(J15,Calculations!$E$13:$E$22,Calculations!$F$13:$F$22,0) -> 3 | L15: =IF(F15="Yes",H15+I15*K15,0) -> 120 | N15: =IF(F15="Yes",IF(M15="",L15,M15),0) -> 120 | O15: =MIN(P15*$O$4,0.95) -> 0.315 | P15: 0.45 | Q15: =MIN(P15*$Q$4,0.95) -> 0.5625 | R15: {=INDEX(O15:Q15,Calculations!$I$13)*(1-Inputs!$C$8)} -> 0.45 | S15: =N15*(1-R15) -> 66 | T15: =N15-S15 -> 54 | U15: =_xlfn.XLOOKUP(G15,Inputs!$B$30:$B$34,Inputs!$G$30:$G$34,0) -> 54.6875 | V15: =T15*U15 -> 2953.125
B16: 10 | C16: Report creation & formatting | D16: Automated, one-click report generation | E16: Core | F16: =_xlfn.XLOOKUP(E16,Calculations!$B$13:$B$18,Calculations!$C$13:$C$18,"No") -> Yes | G16: Sustainability team (full-time) | H16: 20 | I16: 25 | J16: Frameworks | K16: =_xlfn.XLOOKUP(J16,Calculations!$E$13:$E$22,Calculations!$F$13:$F$22,0) -> 3 | L16: =IF(F16="Yes",H16+I16*K16,0) -> 95 | N16: =IF(F16="Yes",IF(M16="",L16,M16),0) -> 95 | O16: =MIN(P16*$O$4,0.95) -> 0.455 | P16: 0.65 | Q16: =MIN(P16*$Q$4,0.95) -> 0.8125 | R16: {=INDEX(O16:Q16,Calculations!$I$13)*(1-Inputs!$C$8)} -> 0.65 | S16: =N16*(1-R16) -> 33.25 | T16: =N16-S16 -> 61.75 | U16: =_xlfn.XLOOKUP(G16,Inputs!$B$30:$B$34,Inputs!$G$30:$G$34,0) -> 54.6875 | V16: =T16*U16 -> 3376.9531
B17: 11 | C17: Dashboard & management updates | D17: Connected outputs – no copying of figures, refreshing charts or reconciling versions | E17: Core | F17: =_xlfn.XLOOKUP(E17,Calculations!$B$13:$B$18,Calculations!$C$13:$C$18,"No") -> Yes | G17: Sustainability team (full-time) | H17: 20 | I17: 20 | J17: Rounds | K17: =_xlfn.XLOOKUP(J17,Calculations!$E$13:$E$22,Calculations!$F$13:$F$22,0) -> 1 | L17: =IF(F17="Yes",H17+I17*K17,0) -> 40 | N17: =IF(F17="Yes",IF(M17="",L17,M17),0) -> 40 | O17: =MIN(P17*$O$4,0.95) -> 0.49 | P17: 0.7 | Q17: =MIN(P17*$Q$4,0.95) -> 0.875 | R17: {=INDEX(O17:Q17,Calculations!$I$13)*(1-Inputs!$C$8)} -> 0.7 | S17: =N17*(1-R17) -> 12 | T17: =N17-S17 -> 28 | U17: =_xlfn.XLOOKUP(G17,Inputs!$B$30:$B$34,Inputs!$G$30:$G$34,0) -> 54.6875 | V17: =T17*U17 -> 1531.25
B18: 12 | C18: Evidence & assurance preparation | D18: Central source documents, references and audit trail for reviewers | E18: Core | F18: =_xlfn.XLOOKUP(E18,Calculations!$B$13:$B$18,Calculations!$C$13:$C$18,"No") -> Yes | G18: Sustainability team (full-time) | H18: 40 | I18: 8 | J18: Entities | K18: =_xlfn.XLOOKUP(J18,Calculations!$E$13:$E$22,Calculations!$F$13:$F$22,0) -> 5 | L18: =IF(F18="Yes",H18+I18*K18,0) -> 80 | N18: =IF(F18="Yes",IF(M18="",L18,M18),0) -> 80 | O18: =MIN(P18*$O$4,0.95) -> 0.315 | P18: 0.45 | Q18: =MIN(P18*$Q$4,0.95) -> 0.5625 | R18: {=INDEX(O18:Q18,Calculations!$I$13)*(1-Inputs!$C$8)} -> 0.45 | S18: =N18*(1-R18) -> 44 | T18: =N18-S18 -> 36 | U18: =_xlfn.XLOOKUP(G18,Inputs!$B$30:$B$34,Inputs!$G$30:$G$34,0) -> 54.6875 | V18: =T18*U18 -> 1968.75
... B24: 18 | C24: Knowledge continuity & handovers | D24: Shared data, methods and workflows instead of individual spreadsheets | E24: Core | F24: =_xlfn.XLOOKUP(E24,Calculations!$B$13:$B$18,Calculations!$C$13:$C$18,"No") -> Yes | G24: Sustainability team (full-time) | H24: 40 | I24: 0 | J24: Fixed | K24: =_xlfn.XLOOKUP(J24,Calculations!$E$13:$E$22,Calculations!$F$13:$F$22,0) -> 0 | L24: =IF(F24="Yes",H24+I24*K24,0) -> 40 | N24: =IF(F24="Yes",IF(M24="",L24,M24),0) -> 40 | O24: =MIN(P24*$O$4,0.95) -> 0.35 | P24: 0.5 | Q24: =MIN(P24*$Q$4,0.95) -> 0.625 | R24: {=INDEX(O24:Q24,Calculations!$I$13)*(1-Inputs!$C$8)} -> 0.5 | S24: =N24*(1-R24) -> 20 | T24: =N24-S24 -> 20 | U24: =_xlfn.XLOOKUP(G24,Inputs!$B$30:$B$34,Inputs!$G$30:$G$34,0) -> 54.6875 | V24: =T24*U24 -> 1093.75
C25: Total | L25: =SUM(L7:L24) -> 1930 | M25: =SUM(M7:M24) -> 0 | N25: =SUM(N7:N24) -> 1930 | R25: =IFERROR(1-S25/N25,0) -> 0.52603627 | S25: =SUM(S7:S24) -> 914.75 | T25: =SUM(T7:T24) -> 1015.25 | V25: =SUM(V7:V24) -> 54447.266
B27: How to read this table
B28: • Benchmark hours = fixed hours + hours per unit × units. Units come from your Inputs (e.g. 10 locations × 1 round = 10 units).
B29: • If you know your actual effort, enter it in 'Your estimate' – it replaces the benchmark. Activities outside the selected modules count as 0.
B30: • Expected reductions reflect what remains with FI: preparation, review, exception handling and administration. Human review and approval remain part of every workflow.
B31: • *Applied reduction = reduction of the selected scenario × (1 − share already covered by your current tool, Inputs C8), so existing capabilities are not credited twice.
B32: • Saved hours are released capacity. They only reduce cash costs if they replace staffing or external spend.
B33: • Only the 'Expected' reduction is entered per activity. Conservative and Optimistic apply the scenario factors in O4 and Q4 (capped at 95%).
B34: • Columns H–K (benchmark mechanics) are grouped – click '+' above the columns to show how benchmark hours are built.

Sheet Results
B2: ="Business case: Footprint Intelligence for "&Inputs!C6 -> Business case: Footprint Intelligence for Your company
B3: ="Compared with today's approach ("&Inputs!C7&") · Scenario: "&Inputs!C10&" · Step 3 of 3 – Results" -> Compared with today's approach (Manual / Excel) · Scenario: Expected · Step 3 of 3 – Results
B5: Headline results
B6: Time saved per year | C6: Recurring annual net benefit | E6: 3-year ROI | G6: Payback period
B7: =Calculations!F30 -> 1015.25 | C7: =Calculations!F36 -> 27947.266 | E7: =Calculations!F45 -> 0.18390723 | G7: =IF(ISNUMBER(Calculations!F48),Calculations!F48&" months","> 36 months") -> 9 months
B8: =TEXT(Calculations!F49,"#,##0")&" working days · "&TEXT(Calculations!F50,"0.0")&" FTE" -> 127 working days · 0.6 FTE | C8: per year from year 2 (capacity + cash) | E8: (3-yr cost today − 3-yr cost with FI) ÷ 3-yr cost with FI | G8: incl. one-time transition costs
B10: Annual view
B11: Item | C11: Year 1 | D11: Year 2 onwards | E11: Explanation
B12: Internal capacity released (value of time saved) | C12: =Calculations!F32*Inputs!C54 -> 32668.359 | D12: =Calculations!F32 -> 54447.266 | E12: Hours saved × fully loaded cost per hour. Year 1 reflects the ramp-up share. Released capacity – not a cash saving unless it reduces staffing or external spend.
B13: Cash savings: software, databases & external services | C13: =Inputs!C43-(Inputs!E43-Inputs!E42) -> 12500 | D13: =C13 -> 12500 | E13: External costs today minus external costs still needed with FI
B14: Footprint Intelligence subscription | C14: =-Inputs!E42 -> -39000 | D14: =C14 -> -39000 | E14: As per your offer
B15: One-time transition costs | C15: =-Calculations!F37 -> -4375 | D15: 0 | E15: Implementation fee, migration, parallel licences and internal onboarding time
B16: Net benefit | C16: =SUM(C12:C15) -> 1793.3594 | D16: =SUM(D12:D15) -> 27947.266
B18: 3-year business case
B19: 3-year view (savings vs. investment) | C19: Year 1 | D19: Years 2–3 | E19: Total 3 years
B20: Internal capacity released (value of time saved) | C20: =C12 -> 32668.359 | D20: =2*D12 -> 108894.53 | E20: =C20+D20 -> 141562.89
B21: Cash savings: software, databases & external services | C21: =C13 -> 12500 | D21: =2*D13 -> 25000 | E21: =C21+D21 -> 37500
B22: Footprint Intelligence subscription | C22: =C14 -> -39000 | D22: =2*D14 -> -78000 | E22: =C22+D22 -> -117000
B23: One-time transition costs | C23: =C15 -> -4375 | D23: 0 | E23: =C23+D23 -> -4375
B24: Net benefit | C24: =SUM(C20:C23) -> 1793.3594 | D24: =SUM(D20:D23) -> 55894.531 | E24: =SUM(E20:E23) -> 57687.891
B25: 3-year ROI (difference ÷ 3-year cost with FI) | E25: =Calculations!F45 -> 0.18390723
B26: Net benefit per €1 spent on Footprint Intelligence (subscription + one-time) | E26: =Calculations!F47 -> 0.47528643
B27: Break-even: FI pays for itself (from year 2) at this share of the expected time savings | E27: =IFERROR(MAX(0,-Calculations!F35)/Calculations!F32,0) -> 0.48670947
B28: Scenario comparison
B29: Metric | C29: Conservative | D29: Expected | E29: Optimistic
B30: Hours saved per year | C30: =Calculations!C30 -> 710.675 | D30: =Calculations!D30 -> 1015.25 | E30: =Calculations!E30 -> 1269.0625
B31: Internal capacity released (€ / year) | C31: =Calculations!C32 -> 38113.086 | D31: =Calculations!D32 -> 54447.266 | E31: =Calculations!E32 -> 68059.082
B32: Net cash impact incl. subscription (€ / year) | C32: =Calculations!C35 -> -26500 | D32: =Calculations!D35 -> -26500 | E32: =Calculations!E35 -> -26500
B33: Recurring annual net benefit (€ / year) | C33: =Calculations!C36 -> 11613.086 | D33: =Calculations!D36 -> 27947.266 | E33: =Calculations!E36 -> 41559.082
B34: Year-1 net benefit (€) | C34: =Calculations!C38 -> -8007.1484 | D34: =Calculations!D38 -> 1793.3594 | E34: =Calculations!E38 -> 9960.4492
B35: 3-year net benefit (€) | C35: =Calculations!C44 -> 15219.023 | D35: =Calculations!D44 -> 57687.891 | E35: =Calculations!E44 -> 93078.613
B36: 3-year ROI | C36: =Calculations!C45 -> 0.042732281 | D36: =Calculations!D45 -> 0.18390723 | E36: =Calculations!E45 -> 0.33446797
B37: Payback (months) | C37: =Calculations!C48 -> 21 | D37: =Calculations!D48 -> 9 | E37: =Calculations!E48 -> 4
B39: Footprint Intelligence vs. alternative software (3 years, selected scenario)
B40: 3-year view vs. alternative software | C40: Alternative software | D40: With Footprint Intelligence | E40: Advantage FI
B41: Internal capacity released (vs. today) | C41: =Calculations!F32*Inputs!C60*(Inputs!C54+2) -> 84937.734 | D41: =E20 -> 141562.89 | E41: =D41-C41 -> 56625.156
B42: Cash savings: software, databases & external services | C42: =3*(Inputs!C43-(Inputs!E43-Inputs!E42)-Inputs!C61) -> 22500 | D42: =E21 -> 37500 | E42: =D42-C42 -> 15000
B43: Software subscription | C43: =-3*Inputs!C58 -> -60000 | D43: =E22 -> -117000 | E43: =D43-C43 -> -57000
B44: One-time transition costs | C44: =-(Inputs!C59+Inputs!D48+Inputs!D49+Inputs!D50) -> -4375 | D44: =E23 -> -4375 | E44: =D44-C44 -> 0
B45: Net benefit over 3 years | C45: =SUM(C41:C44) -> 43062.734 | D45: =SUM(D41:D44) -> 57687.891 | E45: =D45-C45 -> 14625.156
...

Sheet Calculations
B2: Calculations (do not edit) – drop-down lists, scenario engine and chart data
B3: All figures on this sheet are calculated from the Inputs and Activities sheets.
B5: Current approach | D5: Yes / No | F5: Scenario | H5: Rounds per year
B6: Manual / Excel | D6: Yes | F6: Conservative | H6: 1
B7: Other sustainability software | D7: No | F7: Expected | H7: 2
B8: Consultancy-led | F8: Optimistic | H8: 4
B9: Combination | H9: 12
B12: Module | C12: In scope | E12: Driver | F12: Units | H12: Selected scenario | I12: #
B13: Core | C13: Yes | E13: Fixed | F13: 0 | H13: Scenario number | I13: =MATCH(Inputs!C10,$F$6:$F$8,0) -> 2
B14: Carbon accounting | C14: =Inputs!C21 -> Yes | E14: Locations × rounds | F14: =Inputs!C14*Inputs!C9 -> 30
B15: ESG reporting | C15: =Inputs!C22 -> Yes | E15: Entities × rounds | F15: =Inputs!C13*Inputs!C9 -> 5 | H15: Check: capacity value = Activities total | I15: =ROUND(F32-Activities!V25,2)=0 -> TRUE
B16: PCF | C16: =Inputs!C23 -> No | E16: Data providers × rounds | F16: =Inputs!C31*Inputs!C9 -> 25
B17: Supply chain | C17: =Inputs!C24 -> Yes | E17: Entities | F17: =Inputs!C13 -> 5
B18: Decarbonization | C18: =Inputs!C25 -> Yes | E18: Frameworks | F18: =Inputs!C15 -> 3
E19: Questionnaires | F19: =Inputs!C16 -> 10
E20: Suppliers | F20: =Inputs!C17 -> 20
E21: Products | F21: =Inputs!C18 -> 5
E22: Rounds | F22: =Inputs!C9 -> 1
B26: Scenario engine
B27: Metric | C27: Conservative | D27: Expected | E27: Optimistic | F27: Selected
B28: Scenario column | C28: 1 | D28: 2 | E28: 3 | F28: =I13 -> 2
B29: Hours today (per year) | C29: =SUM(Activities!$N$7:$N$24) -> 1930 | D29: =SUM(Activities!$N$7:$N$24) -> 1930 | E29: =SUM(Activities!$N$7:$N$24) -> 1930 | F29: {=INDEX(C29:E29,$I$13)} -> 1930
B30: Hours saved (steady state, per year) | C30: =SUMPRODUCT(Activities!$N$7:$N$24,INDEX(Activities!$O$7:$Q$24,0,C$28))*(1-Inputs!$C$8) -> 710.675 | D30: =SUMPRODUCT(Activities!$N$7:$N$24,INDEX(Activities!$O$7:$Q$24,0,D$28))*(1-Inputs!$C$8) -> 1015.25 | E30: =SUMPRODUCT(Activities!$N$7:$N$24,INDEX(Activities!$O$7:$Q$24,0,E$28))*(1-Inputs!$C$8) -> 1269.0625 | F30: {=INDEX(C30:E30,$I$13)} -> 1015.25
B31: Internal staff cost today (€/yr) | C31: =SUMPRODUCT(Activities!$N$7:$N$24,Activities!$U$7:$U$24) -> 103789.06 | D31: =SUMPRODUCT(Activities!$N$7:$N$24,Activities!$U$7:$U$24) -> 103789.06 | E31: =SUMPRODUCT(Activities!$N$7:$N$24,Activities!$U$7:$U$24) -> 103789.06 | F31: {=INDEX(C31:E31,$I$13)} -> 103789.06
B32: Capacity value released (steady state, €/yr) | C32: =SUMPRODUCT(Activities!$N$7:$N$24,INDEX(Activities!$O$7:$Q$24,0,C$28),Activities!$U$7:$U$24)*(1-Inputs!$C$8) -> 38113.086 | D32: =SUMPRODUCT(Activities!$N$7:$N$24,INDEX(Activities!$O$7:$Q$24,0,D$28),Activities!$U$7:$U$24)*(1-Inputs!$C$8) -> 54447.266 | E32: =SUMPRODUCT(Activities!$N$7:$N$24,INDEX(Activities!$O$7:$Q$24,0,E$28),Activities!$U$7:$U$24)*(1-Inputs!$C$8) -> 68059.082 | F32: {=INDEX(C32:E32,$I$13)} -> 54447.266
B33: External costs today (€/yr) | C33: =Inputs!$C$43 -> 20000 | D33: =Inputs!$C$43 -> 20000 | E33: =Inputs!$C$43 -> 20000 | F33: {=INDEX(C33:E33,$I$13)} -> 20000
B34: External costs with FI incl. subscription (€/yr) | C34: =Inputs!$E$43 -> 46500 | D34: =Inputs!$E$43 -> 46500 | E34: =Inputs!$E$43 -> 46500 | F34: {=INDEX(C34:E34,$I$13)} -> 46500
B35: Net cash impact (€/yr) | C35: =C33-C34 -> -26500 | D35: =D33-D34 -> -26500 | E35: =E33-E34 -> -26500 | F35: {=INDEX(C35:E35,$I$13)} -> -26500
B36: Recurring annual net benefit (€/yr) | C36: =C32+C35 -> 11613.086 | D36: =D32+D35 -> 27947.266 | E36: =E32+E35 -> 41559.082 | F36: {=INDEX(C36:E36,$I$13)} -> 27947.266
B37: One-time transition costs (€) | C37: =Inputs!$D$51 -> 4375 | D37: =Inputs!$D$51 -> 4375 | E37: =Inputs!$D$51 -> 4375 | F37: {=INDEX(C37:E37,$I$13)} -> 4375
B38: Year-1 net benefit (€) | C38: =C32*Inputs!$C$54+C35-C37 -> -8007.1484 | D38: =D32*Inputs!$C$54+D35-D37 -> 1793.3594 | E38: =E32*Inputs!$C$54+E35-E37 -> 9960.4492 | F38: {=INDEX(C38:E38,$I$13)} -> 1793.3594
B39: Current annual cost – internal + external (€/yr) | C39: =C31+C33 -> 123789.06 | D39: =D31+D33 -> 123789.06 | E39: =E31+E33 -> 123789.06 | F39: {=INDEX(C39:E39,$I$13)} -> 123789.06
B40: Annual cost with FI – steady state (€/yr) | C40: =C31-C32+C34 -> 112175.98 | D40: =D31-D32+D34 -> 95841.797 | E40: =E31-E32+E34 -> 82229.98 | F40: {=INDEX(C40:E40,$I$13)} -> 95841.797
B41: Year-1 cost with FI (€) | C41: =C31-C32*Inputs!$C$54+C34+C37 -> 131796.21 | D41: =D31-D32*Inputs!$C$54+D34+D37 -> 121995.7 | E41: =E31-E32*Inputs!$C$54+E34+E37 -> 113828.61 | F41: {=INDEX(C41:E41,$I$13)} -> 121995.7
B42: 3-year cost – current approach (€) | C42: =3*C39 -> 371367.19 | D42: =3*D39 -> 371367.19 | E42: =3*E39 -> 371367.19 | F42: {=INDEX(C42:E42,$I$13)} -> 371367.19
B43: 3-year cost – with FI (€) | C43: =C41+2*C40 -> 356148.16 | D43: =D41+2*D40 -> 313679.3 | E43: =E41+2*E40 -> 278288.57 | F43: {=INDEX(C43:E43,$I$13)} -> 313679.3
B44: 3-year net benefit (€) | C44: =C42-C43 -> 15219.023 | D44: =D42-D43 -> 57687.891 | E44: =E42-E43 -> 93078.613 | F44: {=INDEX(C44:E44,$I$13)} -> 57687.891
B45: 3-year ROI (%) | C45: =IFERROR(C44/C43,0) -> 0.042732281 | D45: =IFERROR(D44/D43,0) -> 0.18390723 | E45: =IFERROR(E44/E43,0) -> 0.33446797 | F45: {=INDEX(C45:E45,$I$13)} -> 0.18390723
B46: 3-year FI investment – subscription + one-time (€) | C46: =3*Inputs!$E$42+C37 -> 121375 | D46: =3*Inputs!$E$42+D37 -> 121375 | E46: =3*Inputs!$E$42+E37 -> 121375 | F46: {=INDEX(C46:E46,$I$13)} -> 121375
B47: 3-year net benefit per €1 invested in FI | C47: =IFERROR(C44/C46,0) -> 0.12538845 | D47: =IFERROR(D44/D46,0) -> 0.47528643 | E47: =IFERROR(E44/E46,0) -> 0.76686808 | F47: {=INDEX(C47:E47,$I$13)} -> 0.47528643
...
